<mujoco model="fr3">
  <compiler angle="radian" meshdir="../assets/"/>

  <size nkey="1"/>

  <default>
    <default class="fr3">
      <joint armature="0.1" damping="1"/>
      <site size="0.001 0.005 0.005" group="3" rgba="0.5 0.5 0.5 0.3"/>
      <general biastype="affine" biasprm="0 -1"/>
      <default class="visual">
        <geom type="mesh" contype="0" conaffinity="0" group="2"/>
      </default>
      <default class="collision">
        <geom type="mesh" group="3"/>
      </default>
    </default>
  </default>

  <custom>
    <numeric name="init_pos" size="7" data="0 -1.3 0 -2.5 0 1.57079 -0.2353"/>
  </custom>

  <asset>
    <material name="black" rgba="0.2 0.2 0.2 1"/>
    <material name="white"/>
    <material name="red" rgba="1 0.072272 0.039546 1"/>
    <material name="gray" rgba="0.863156 0.863156 0.863157 1"/>
    <material name="button_green" rgba="0.102241 0.571125 0.102242 1"/>
    <material name="button_red" rgba="0.520996 0.008023 0.013702 1"/>
    <material name="button_blue" rgba="0.024157 0.445201 0.737911 1"/>
    <mesh name="link0_0" content_type="model/obj" file="link0_0.obj"/>
    <mesh name="link0_1" content_type="model/obj" file="link0_1.obj"/>
    <mesh name="link0_2" content_type="model/obj" file="link0_2.obj"/>
    <mesh name="link0_3" content_type="model/obj" file="link0_3.obj"/>
    <mesh name="link0_4" content_type="model/obj" file="link0_4.obj"/>
    <mesh name="link0_5" content_type="model/obj" file="link0_5.obj"/>
    <mesh name="link0_6" content_type="model/obj" file="link0_6.obj"/>
    <mesh name="link0" content_type="model/stl" file="link0.stl"/>
    <mesh name="link1" content_type="model/obj" file="link1.obj"/>
    <mesh name="link2" content_type="model/obj" file="link2.obj"/>
    <mesh name="link3_0" content_type="model/obj" file="link3_0.obj"/>
    <mesh name="link3_1" content_type="model/obj" file="link3_1.obj"/>
    <mesh name="link3" content_type="model/stl" file="link3.stl"/>
    <mesh name="link4_0" content_type="model/obj" file="link4_0.obj"/>
    <mesh name="link4_1" content_type="model/obj" file="link4_1.obj"/>
    <mesh name="link4" content_type="model/stl" file="link4.stl"/>
    <mesh name="link5_0" content_type="model/obj" file="link5_0.obj"/>
    <mesh name="link5_1" content_type="model/obj" file="link5_1.obj"/>
    <mesh name="link5_2" content_type="model/obj" file="link5_2.obj"/>
    <mesh name="link5" content_type="model/stl" file="link5.stl"/>
    <mesh name="link6_0" content_type="model/obj" file="link6_0.obj"/>
    <mesh name="link6_1" content_type="model/obj" file="link6_1.obj"/>
    <mesh name="link6_2" content_type="model/obj" file="link6_2.obj"/>
    <mesh name="link6_3" content_type="model/obj" file="link6_3.obj"/>
    <mesh name="link6_4" content_type="model/obj" file="link6_4.obj"/>
    <mesh name="link6_5" content_type="model/obj" file="link6_5.obj"/>
    <mesh name="link6_6" content_type="model/obj" file="link6_6.obj"/>
    <mesh name="link6_7" content_type="model/obj" file="link6_7.obj"/>
    <mesh name="link6" content_type="model/stl" file="link6.stl"/>
    <mesh name="link7_0" content_type="model/obj" file="link7_0.obj"/>
    <mesh name="link7_1" content_type="model/obj" file="link7_1.obj"/>
    <mesh name="link7_2" content_type="model/obj" file="link7_2.obj"/>
    <mesh name="link7_3" content_type="model/obj" file="link7_3.obj"/>
    <mesh name="link7" content_type="model/stl" file="link7.stl"/>
    <mesh name="fr3_ati" content_type="model/stl" file="fr3_ati.STL" scale="0.001 0.001 0.001"/>
    <mesh name="FT_ATI_M8" content_type="model/stl" file="FT_ATI_M8.STL" scale="0.001 0.001 0.001"/>
    <mesh name="ati_pika_new" content_type="model/stl" file="ati_pika_new.STL" scale="0.001 0.001 0.001"/>
    <mesh name="pika_gripper_base_link" content_type="model/stl" file="pika_gripper_base_link.STL"/>
    <mesh name="pika_gripper_left_link" content_type="model/stl" file="pika_gripper_left_link.STL"/>
    <mesh name="pika_gripper_right_link" content_type="model/stl" file="pika_gripper_right_link.STL"/>
  </asset>

  <worldbody>
    <body name="base" childclass="fr3">
      <body name="fr3_link0">
        <geom name="fr3_link0_visual" class="visual" material="black" mesh="link0_0"/>
        <geom class="visual" material="white" mesh="link0_1"/>
        <geom class="visual" material="white" mesh="link0_2"/>
        <geom class="visual" material="white" mesh="link0_3"/>
        <geom class="visual" material="white" mesh="link0_4"/>
        <geom class="visual" material="red" mesh="link0_5"/>
        <geom class="visual" material="black" mesh="link0_6"/>
        <geom name="fr3_link0_collision" class="collision" mesh="link0"/>
        <body name="fr3_link1" pos="0 0 0.333">
          <inertial pos="4.128e-07 -0.0181251 -0.0386036" quat="0.998098 -0.0605364 0.00380499 0.0110109" mass="2.92747" diaginertia="0.0239286 0.0227246 0.00610634"/>
          <joint name="fr3_joint1" pos="0 0 0" axis="0 0 1" range="-2.7437 2.7437" actuatorfrcrange="-87 87" damping="0.003" frictionloss="0.2"/>
          <geom name="fr3_link1_visual" class="visual" material="white" mesh="link1"/>
          <geom name="fr3_link1_collision" class="collision" mesh="link1"/>
          <body name="fr3_link2" quat="0.707107 -0.707107 0 0">
            <inertial pos="0.00318289 -0.0743222 0.00881461" quat="0.502599 0.584437 -0.465998 0.434366" mass="2.93554" diaginertia="0.0629567 0.0411924 0.0246371"/>
            <joint name="fr3_joint2" pos="0 0 0" axis="0 0 1" range="-1.7837 1.7837" actuatorfrcrange="-87 87" damping="0.003" frictionloss="0.2"/>
            <geom name="fr3_link2_visual" class="visual" material="white" mesh="link2"/>
            <geom name="fr3_link2_collision" class="collision" mesh="link2"/>
            <body name="fr3_link3" pos="0 -0.316 0" quat="0.707107 0.707107 0 0">
              <inertial pos="0.0407016 -0.00482006 -0.0289731" quat="0.921025 -0.244161 0.155272 0.260745" mass="2.2449" diaginertia="0.0267409 0.0189869 0.0171587"/>
              <joint name="fr3_joint3" pos="0 0 0" axis="0 0 1" range="-2.9007 2.9007" actuatorfrcrange="-87 87" damping="0.003" frictionloss="0.2"/>
              <geom class="visual" material="white" mesh="link3_0"/>
              <geom class="visual" material="black" mesh="link3_1"/>
              <geom name="fr3_link3_collision" class="collision" mesh="link3"/>
              <body name="fr3_link4" pos="0.0825 0 0" quat="0.707107 0.707107 0 0">
                <inertial pos="-0.0459101 0.0630493 -0.00851879" quat="0.438018 0.803311 0.00937812 0.403414" mass="2.6156" diaginertia="0.05139 0.0372717 0.0160047"/>
                <joint name="fr3_joint4" pos="0 0 0" axis="0 0 1" range="-3.0421 -0.1518" actuatorfrcrange="-87 87" damping="0.003" frictionloss="0.2"/>
                <geom class="visual" material="white" mesh="link4_0"/>
                <geom class="visual" material="black" mesh="link4_1"/>
                <geom name="fr3_link4_collision" class="collision" mesh="link4"/>
                <body name="fr3_link5" pos="-0.0825 0.384 0" quat="0.707107 -0.707107 0 0">
                  <inertial pos="-0.00160396 0.0292536 -0.0972966" quat="0.919031 0.125604 0.0751531 -0.366003" mass="2.32712" diaginertia="0.0579335 0.0449144 0.0130634"/>
                  <joint name="fr3_joint5" pos="0 0 0" axis="0 0 1" range="-2.8065 2.8065" actuatorfrcrange="-12 12" damping="0.003" frictionloss="0.2"/>
                  <geom class="visual" material="white" mesh="link5_0"/>
                  <geom class="visual" material="white" mesh="link5_1"/>
                  <geom class="visual" material="black" mesh="link5_2"/>
                  <geom name="fr3_link5_collision" class="collision" mesh="link5"/>
                  <body name="fr3_link6" quat="0.707107 0.707107 0 0">
                    <inertial pos="0.0597131 -0.0410295 -0.0101693" quat="0.621301 0.552665 0.510011 0.220081" mass="1.81704" diaginertia="0.0175039 0.0161123 0.00193529"/>
                    <joint name="fr3_joint6" pos="0 0 0" axis="0 0 1" range="0.5445 4.5169" actuatorfrcrange="-12 12" damping="0.003" frictionloss="0.2"/>
                    <geom class="visual" material="button_green" mesh="link6_0"/>
                    <geom class="visual" material="white" mesh="link6_1"/>
                    <geom class="visual" material="white" mesh="link6_2"/>
                    <geom class="visual" material="gray" mesh="link6_3"/>
                    <geom class="visual" material="button_red" mesh="link6_4"/>
                    <geom class="visual" material="white" mesh="link6_5"/>
                    <geom class="visual" material="black" mesh="link6_6"/>
                    <geom class="visual" material="button_blue" mesh="link6_7"/>
                    <geom name="fr3_link6_collision" class="collision" mesh="link6"/>
                    <body name="fr3_link7" pos="0.088 0 0" quat="0.707107 0.707107 0 0">
                      <inertial pos="-0.00401826 0.00457211 0.0803951" quat="0.997617 0.0260292 -0.0371784 -0.0519723" mass="1.18326" diaginertia="0.0139646 0.0137417 0.000969345"/>
                      <joint name="fr3_joint7" pos="0 0 0" axis="0 0 1" range="-3.0159 3.0159" actuatorfrcrange="-12 12" damping="0.003" frictionloss="0.2"/>
                      <geom class="visual" material="black" mesh="link7_0"/>
                      <geom class="visual" material="white" mesh="link7_1"/>
                      <geom class="visual" material="white" mesh="link7_2"/>
                      <geom class="visual" material="black" mesh="link7_3"/>
                      <geom name="fr3_link7_collision" class="collision" mesh="link7"/>
                      <body name="gripper_base">
                        <geom class="visual" pos="-0.041 -0.04 0.1067" quat="0.5 0.5 0.5 0.5" material="white" mesh="fr3_ati"/>
                        <geom class="collision" pos="-0.041 -0.04 0.1067" quat="0.5 0.5 0.5 0.5" mesh="fr3_ati"/>
                        <geom class="visual" pos="0.041 -0.04 0.1663" quat="-0.499602 0.500398 0.500398 -0.499602" material="white" mesh="FT_ATI_M8"/>
                        <geom class="collision" pos="0.041 -0.04 0.1663" quat="-0.499602 0.500398 0.500398 -0.499602" mesh="FT_ATI_M8"/>
                        <geom class="visual" pos="-0.046 0.076 0.1865" quat="-0.5 0.5 -0.5 0.5" material="white" mesh="ati_pika_new"/>
                        <geom class="collision" pos="-0.046 0.076 0.1865" quat="-0.5 0.5 -0.5 0.5" mesh="ati_pika_new"/>
                        <geom class="visual" pos="-0.001 -2.67949e-10 0.1765" quat="0.25564 0.659279 -0.25564 0.659279" material="black" mesh="pika_gripper_base_link"/>
                        <geom class="collision" pos="-0.001 -2.67949e-10 0.1765" quat="0.25564 0.659279 -0.25564 0.659279" mesh="pika_gripper_base_link"/>
                        <camera name="ee_cam" pos="0 0 0.255" quat="1.89468e-08 0.707108 0.707105 1.89469e-08" fovy="120"/>
                      </body>
                      <body name="gripper_left_link" pos="-0.0559287 -0.0696997 0.258" quat="0.25564 0.659279 -0.25564 0.659279">
                        <inertial pos="0.033255 -0.014661 -0.0057614" quat="0.606445 0.607197 0.362695 0.363302" mass="0.033674" diaginertia="4.22483e-05 3.9744e-05 7.51567e-06"/>
                        <joint name="gripper_left_joint" pos="0 0 0" axis="0 1 0" type="slide" range="-0.05 0" actuatorfrcrange="-100 100"/>
                        <geom class="visual" material="black" mesh="pika_gripper_left_link"/>
                        <geom class="collision" mesh="pika_gripper_left_link"/>
                      </body>
                      <body name="gripper_right_link" pos="0.0634224 0.0610601 0.258" quat="0.25564 0.659279 -0.25564 0.659279">
                        <inertial pos="0.033255 0.014661 -0.0058113" quat="0.362693 0.363304 0.606443 0.607199" mass="0.033674" diaginertia="4.22483e-05 3.9744e-05 7.51567e-06"/>
                        <joint name="gripper_right_joint" pos="0 0 0" axis="0 1 0" type="slide" range="0 0.05" actuatorfrcrange="-100 100"/>
                        <geom class="visual" material="black" mesh="pika_gripper_right_link"/>
                        <geom class="collision" mesh="pika_gripper_right_link"/>
                      </body>
                    </body>
                  </body>
                </body>
              </body>
            </body>
          </body>
        </body>
      </body>
    </body>
  </worldbody>

  <contact>
    <exclude body1="gripper_base" body2="gripper_left_link"/>
    <exclude body1="gripper_base" body2="gripper_right_link"/>
  </contact>

  <equality>
    <joint joint1="gripper_left_joint" joint2="gripper_right_joint" polycoef="0 -1 0 0 0"/>
  </equality>

  <tendon>
    <fixed name="split">
      <joint joint="gripper_left_joint" coef="-1.087"/>
      <joint joint="gripper_right_joint" coef="1.087"/>
    </fixed>
  </tendon>

  <actuator>
    <general name="fr3_actuator1" class="fr3" joint="fr3_joint1" ctrlrange="-40 40" biastype="none"/>
    <general name="fr3_actuator2" class="fr3" joint="fr3_joint2" ctrlrange="-40 40" biastype="none"/>
    <general name="fr3_actuator3" class="fr3" joint="fr3_joint3" ctrlrange="-40 40" biastype="none"/>
    <general name="fr3_actuator4" class="fr3" joint="fr3_joint4" ctrlrange="-40 40" biastype="none"/>
    <general name="fr3_actuator5" class="fr3" joint="fr3_joint5" ctrlrange="-40 40" biastype="none"/>
    <general name="fr3_actuator6" class="fr3" joint="fr3_joint6" ctrlrange="-40 40" biastype="none"/>
    <general name="fr3_actuator7" class="fr3" joint="fr3_joint7" ctrlrange="-40 40" biastype="none"/>
    <general name="pika_gripper_actuator" tendon="split" ctrlrange="0 1" biastype="affine" gainprm="-3" biasprm="0 3"/>
  </actuator>

  <keyframe>
    <key name="home" qpos="0 -0.785 0 -2.355 0 1.57079 0.785 -0.04 0.04"/>
  </keyframe>
</mujoco>
